Workbook

Sheet 订单明细
A1: 2026年10月销售订单明细（自动生成）
A2: 统计期间 | B2: 2026-10
A3: 订单编号 | B3: 订单日期 | C3: 客户编号 | D3: 客户名称 | E3: 城市 | F3: 商品编号 | G3: 商品名称 | H3: 分类 | I3: 数量 | J3: 单价 | K3: 原价金额 | L3: 折扣率 | M3: 优惠金额 | N3: 运费 | O3: 应付金额 | P3: 币种 | Q3: 已付款 | R3: 订单状态 | S3: 销售员 | T3: 渠道 | U3: 省份 | V3: 收件人 | W3: 电话 | X3: 备注 | Y3: 外部流水号 | Z3: 退货数量 | AA3: 发票抬头 | AB3: 发票已开 | AC3: 预留空列 | AD3: 税率 | AE3: 预计发货日期 | AF3: 校验备注
A4: ORD-202610-100001 | B4: 45900.5 | C4: C001 | D4: ='客户档案'!B3 -> 张三 | E4: 上海 | F4: P001 | G4: ='商品目录'!B3 -> 机械键盘 | H4: 外设 | I4: 2 | J4: 99 | K4: =I4*J4 -> 198 | L4: 0 | M4: =K4*L4 -> 0 | N4: 0 | O4: =K4-M4+N4 -> 198 | P4: CNY | Q4: FALSE | R4: 待付款 | S4: 李四 | T4: 网页 | U4: 上海 | V4: 张三 | W4: 0138000100001 | Y4: 9.0071993e+15 | Z4: 2 | AA4: 张三 | AB4: FALSE | AD4: 0.125 | AE4: 45902.5 | AF4: #N/A
A5: ORD-202610-100002 | B5: 45901.5 | C5: C002 | D5: ='客户档案'!B4 -> Acme, Inc. | E5: 北京 | F5: P002 | G5: ='商品目录'!B4 -> 显示器 | H5: 显示设备 | I5: 4 | J5: 129 | K5: =I5*J5 -> 516 | L5: 0.5 | M5: =K5*L5 -> 258 | N5: 10 | O5: =K5-M5+N5 -> 268 | P5: CNY | Q5: TRUE | R5: 已完成 | S5: 王五 | T5: 门店 | U5: 北京 | V5: Acme, Inc. | W5: 0138000100002 | X5: 加急,周五前送达 | Y5: 9.0071993e+15 | Z5: 0 | AA5: Acme, Inc. | AB5: TRUE | AD5: 0.125 | AE5: 45903.5 | AF5: 正常
A6: ORD-202610-100003 | B6: 45902.5 | C6: C003 | D6: ='客户档案'!B5 -> 研发"中心" | E6: 深圳 | F6: P003 | G6: ='商品目录'!B5 -> 办公椅 | H6: 家具 | I6: 6 | J6: 45 | K6: =I6*J6 -> 270 | L6: 0 | M6: =K6*L6 -> 0 | N6: 20 | O6: =K6-M6+N6 -> 290 | P6: CNY | Q6: TRUE | R6: 已完成 | S6: 赵六 | T6: API | U6: 广东 | V6: 研发"中心" | W6: 0138000100003 | X6: 收货前联系"前台" | Y6: 9.0071993e+15 | Z6: 0 | AA6: 研发"中心" | AB6: FALSE | AD6: 0.125 | AE6: 45904.5 | AF6: 正常
A7: ORD-202610-100004 | B7: 45903.5 | C7: C001 | D7: ='客户档案'!B3 -> 张三 | E7: 杭州 | F7: P004 | G7: ='商品目录'!B6 -> 多功能"支架" | H7: 配件 | I7: 8 | J7: 8 | K7: =I7*J7 -> 64 | L7: 0.5 | M7: =K7*L7 -> 32 | N7: 0 | O7: =K7-M7+N7 -> 32 | P7: CNY | Q7: TRUE | R7: 已完成 | S7: 李四 | T7: 网页 | U7: 浙江 | V7: 张三 | W7: 0138000100004 | X7: 第一行 第二行 | Y7: 9.0071993e+15 | Z7: 0 | AA7: 张三 | AB7: TRUE | AD7: 0.125 | AE7: 45905.5 | AF7: 正常
A8: ORD-202610-100005 | B8: 45904.5 | C8: C002 | D8: ='客户档案'!B4 -> Acme, Inc. | E8: 上海 | F8: P001 | G8: ='商品目录'!B3 -> 机械键盘 | H8: 外设 | I8: 10 | J8: 99 | K8: =I8*J8 -> 990 | L8: 0 | M8: =K8*L8 -> 0 | N8: 10 | O8: =K8-M8+N8 -> 1000 | P8: CNY | Q8: FALSE | R8: 待付款 | S8: 王五 | T8: 门店 | U8: 上海 | V8: Acme, Inc. | W8: 0138000100005 | Y8: 9.0071993e+15 | Z8: 0 | AA8: Acme, Inc. | AB8: FALSE | AD8: 0.125 | AE8: 45906.5 | AF8: 正常
A9: ORD-202610-100006 | B9: 45905.5 | C9: C003 | D9: ='客户档案'!B5 -> 研发"中心" | E9: 北京 | F9: P002 | G9: ='商品目录'!B4 -> 显示器 | H9: 显示设备 | I9: 2 | J9: 129 | K9: =I9*J9 -> 258 | L9: 0.5 | M9: =K9*L9 -> 129 | N9: 20 | O9: =K9-M9+N9 -> 149 | P9: CNY | Q9: TRUE | R9: 已完成 | S9: 赵六 | T9: API | U9: 北京 | V9: 研发"中心" | W9: 0138000100006 | X9: 加急,周五前送达 | Y9: 9.0071993e+15 | Z9: 0 | AA9: 研发"中心" | AB9: TRUE | AD9: 0.125 | AE9: 45907.5 | AF9: 正常
A10: ORD-202610-100007 | B10: 45906.5 | C10: C001 | D10: ='客户档案'!B3 -> 张三 | E10: 深圳 | F10: P003 | G10: ='商品目录'!B5 -> 办公椅 | H10: 家具 | I10: 4 | J10: 45 | K10: =I10*J10 -> 180 | L10: 0 | M10: =K10*L10 -> 0 | N10: 0 | O10: =K10-M10+N10 -> 180 | P10: CNY | Q10: TRUE | R10: 已完成 | S10: 李四 | T10: 网页 | U10: 广东 | V10: 张三 | W10: 0138000100007 | X10: 收货前联系"前台" | Y10: 9.0071993e+15 | Z10: 0 | AA10: 张三 | AB10: FALSE | AD10: 0.125 | AE10: 45908.5 | AF10: 正常
A11: ORD-202610-100008 | B11: 45907.5 | C11: C002 | D11: ='客户档案'!B4 -> Acme, Inc. | E11: 杭州 | F11: P004 | G11: ='商品目录'!B6 -> 多功能"支架" | H11: 配件 | I11: 6 | J11: 8 | K11: =I11*J11 -> 48 | L11: 0.5 | M11: =K11*L11 -> 24 | N11: 10 | O11: =K11-M11+N11 -> 34 | P11: CNY | Q11: TRUE | R11: 已完成 | S11: 王五 | T11: 门店 | U11: 浙江 | V11: Acme, Inc. | W11: 0138000100008 | X11: 第一行 第二行 | Y11: 9.0071993e+15 | Z11: 0 | AA11: Acme, Inc. | AB11: TRUE | AD11: 0.125 | AE11: 45909.5 | AF11: 正常
A12: ORD-202610-100009 | B12: 45908.5 | C12: C003 | D12: ='客户档案'!B5 -> 研发"中心" | E12: 上海 | F12: P001 | G12: ='商品目录'!B3 -> 机械键盘 | H12: 外设 | I12: 8 | J12: 99 | K12: =I12*J12 -> 792 | L12: 0 | M12: =K12*L12 -> 0 | N12: 20 | O12: =K12-M12+N12 -> 812 | P12: CNY | Q12: FALSE | R12: 待付款 | S12: 赵六 | T12: API | U12: 上海 | V12: 研发"中心" | W12: 0138000100009 | Y12: 9.0071993e+15 | Z12: 0 | AA12: 研发"中心" | AB12: FALSE | AD12: 0.125 | AE12: 45910.5 | AF12: 正常
A13: ORD-202610-100010 | B13: 45909.5 | C13: C001 | D13: ='客户档案'!B3 -> 张三 | E13: 北京 | F13: P002 | G13: ='商品目录'!B4 -> 显示器 | H13: 显示设备 | I13: 10 | J13: 129 | K13: =I13*J13 -> 1290 | L13: 0.5 | M13: =K13*L13 -> 645 | N13: 0 | O13: =K13-M13+N13 -> 645 | P13: CNY | Q13: TRUE | R13: 已完成 | S13: 李四 | T13: 网页 | U13: 北京 | V13: 张三 | W13: 0138000100010 | X13: 加急,周五前送达 | Y13: 9.0071993e+15 | Z13: 0 | AA13: 张三 | AB13: TRUE | AD13: 0.125 | AE13: 45911.5 | AF13: 正常
A14: ORD-202610-100011 | B14: 45910.5 | C14: C002 | D14: ='客户档案'!B4 -> Acme, Inc. | E14: 深圳 | F14: P003 | G14: ='商品目录'!B5 -> 办公椅 | H14: 家具 | I14: 2 | J14: 45 | K14: =I14*J14 -> 90 | L14: 0 | M14: =K14*L14 -> 0 | N14: 10 | O14: =K14-M14+N14 -> 100 | P14: CNY | Q14: TRUE | R14: 已完成 | S14: 王五 | T14: 门店 | U14: 广东 | V14: Acme, Inc. | W14: 0138000100011 | X14: 收货前联系"前台" | Y14: 9.0071993e+15 | Z14: 0 | AA14: Acme, Inc. | AB14: FALSE | AD14: 0.125 | AE14: 45912.5 | AF14: 正常
A15: ORD-202610-100012 | B15: 45911.5 | C15: C003 | D15: ='客户档案'!B5 -> 研发"中心" | E15: 杭州 | F15: P004 | G15: ='商品目录'!B6 -> 多功能"支架" | H15: 配件 | I15: 4 | J15: 8 | K15: =I15*J15 -> 32 | L15: 0.5 | M15: =K15*L15 -> 16 | N15: 20 | O15: =K15-M15+N15 -> 36 | P15: CNY | Q15: TRUE | R15: 已完成 | S15: 赵六 | T15: API | U15: 浙江 | V15: 研发"中心" | W15: 0138000100012 | X15: 第一行 第二行 | Y15: 9.0071993e+15 | Z15: 0 | AA15: 研发"中心" | AB15: TRUE | AD15: 0.125 | AE15: 45913.5 | AF15: 正常
A16: ORD-202610-100013 | B16: 45912.5 | C16: C001 | D16: ='客户档案'!B3 -> 张三 | E16: 上海 | F16: P001 | G16: ='商品目录'!B3 -> 机械键盘 | H16: 外设 | I16: 6 | J16: 99 | K16: =I16*J16 -> 594 | L16: 0 | M16: =K16*L16 -> 0 | N16: 0 | O16: =K16-M16+N16 -> 594 | P16: CNY | Q16: FALSE | R16: 待付款 | S16: 李四 | T16: 网页 | U16: 上海 | V16: 张三 | W16: 0138000100013 | Y16: 9.0071993e+15 | Z16: 0 | AA16: 张三 | AB16: FALSE | AD16: 0.125 | AE16: 45914.5 | AF16: 正常
A17: ORD-202610-100014 | B17: 45913.5 | C17: C002 | D17: ='客户档案'!B4 -> Acme, Inc. | E17: 北京 | F17: P002 | G17: ='商品目录'!B4 -> 显示器 | H17: 显示设备 | I17: 8 | J17: 129 | K17: =I17*J17 -> 1032 | L17: 0.5 | M17: =K17*L17 -> 516 | N17: 10 | O17: =K17-M17+N17 -> 526 | P17: CNY | Q17: TRUE | R17: 已完成 | S17: 王五 | T17: 门店 | U17: 北京 | V17: Acme, Inc. | W17: 0138000100014 | X17: 加急,周五前送达 | Y17: 9.0071993e+15 | Z17: 0 | AA17: Acme, Inc. | AB17: TRUE | AD17: 0.125 | AE17: 45915.5 | AF17: 正常
A18: ORD-202610-100015 | B18: 45914.5 | C18: C003 | D18: ='客户档案'!B5 -> 研发"中心" | E18: 深圳 | F18: P003 | G18: ='商品目录'!B5 -> 办公椅 | H18: 家具 | I18: 10 | J18: 45 | K18: =I18*J18 -> 450 | L18: 0 | M18: =K18*L18 -> 0 | N18: 20 | O18: =K18-M18+N18 -> 470 | P18: CNY | Q18: TRUE | R18: 已完成 | S18: 赵六 | T18: API | U18: 广东 | V18: 研发"中心" | W18: 0138000100015 | X18: 收货前联系"前台" | Y18: 9.0071993e+15 | Z18: 0 | AA18: 研发"中心" | AB18: FALSE | AD18: 0.125 | AE18: 45916.5 | AF18: 正常
A19: ORD-202610-100016 | B19: 45915.5 | C19: C001 | D19: ='客户档案'!B3 -> 张三 | E19: 杭州 | F19: P004 | G19: ='商品目录'!B6 -> 多功能"支架" | H19: 配件 | I19: 2 | J19: 8 | K19: =I19*J19 -> 16 | L19: 0.5 | M19: =K19*L19 -> 8 | N19: 0 | O19: =K19-M19+N19 -> 8 | P19: CNY | Q19: TRUE | R19: 已完成 | S19: 李四 | T19: 网页 | U19: 浙江 | V19: 张三 | W19: 0138000100016 | X19: 第一行 第二行 | Y19: 9.0071993e+15 | Z19: 0 | AA19: 张三 | AB19: TRUE | AD19: 0.125 | AE19: 45917.5 | AF19: 正常
A20: ORD-202610-100017 | B20: 45916.5 | C20: C002 | D20: ='客户档案'!B4 -> Acme, Inc. | E20: 上海 | F20: P001 | G20: ='商品目录'!B3 -> 机械键盘 | H20: 外设 | I20: 4 | J20: 99 | K20: =I20*J20 -> 396 | L20: 0 | M20: =K20*L20 -> 0 | N20: 10 | O20: =K20-M20+N20 -> 406 | P20: CNY | Q20: FALSE | R20: 待付款 | S20: 王五 | T20: 门店 | U20: 上海 | V20: Acme, Inc. | W20: 0138000100017 | Y20: 9.0071993e+15 | Z20: 0 | AA20: Acme, Inc. | AB20: FALSE | AD20: 0.125 | AE20: 45918.5 | AF20: 正常
A21: ORD-202610-100018 | B21: 45917.5 | C21: C003 | D21: ='客户档案'!B5 -> 研发"中心" | E21: 北京 | F21: P002 | G21: ='商品目录'!B4 -> 显示器 | H21: 显示设备 | I21: 6 | J21: 129 | K21: =I21*J21 -> 774 | L21: 0.5 | M21: =K21*L21 -> 387 | N21: 20 | O21: =K21-M21+N21 -> 407 | P21: CNY | Q21: TRUE | R21: 已完成 | S21: 赵六 | T21: API | U21: 北京 | V21: 研发"中心" | W21: 0138000100018 | X21: 加急,周五前送达 | Y21: 9.0071993e+15 | Z21: 2 | AA21: 研发"中心" | AB21: TRUE | AD21: 0.125 | AE21: 45919.5 | AF21: 正常
A22: ORD-202610-100019 | B22: 45918.5 | C22: C001 | D22: ='客户档案'!B3 -> 张三 | E22: 深圳 | F22: P003 | G22: ='商品目录'!B5 -> 办公椅 | H22: 家具 | I22: 8 | J22: 45 | K22: =I22*J22 -> 360 | L22: 0 | M22: =K22*L22 -> 0 | N22: 0 | O22: =K22-M22+N22 -> 360 | P22: CNY | Q22: TRUE | R22: 已完成 | S22: 李四 | T22: 网页 | U22: 广东 | V22: 张三 | W22: 0138000100019 | X22: 收货前联系"前台" | Y22: 9.0071993e+15 | Z22: 0 | AA22: 张三 | AB22: FALSE | AD22: 0.125 | AE22: 45920.5 | AF22: 正常
A23: ORD-202610-100020 | B23: 45919.5 | C23: C002 | D23: ='客户档案'!B4 -> Acme, Inc. | E23: 杭州 | F23: P004 | G23: ='商品目录'!B6 -> 多功能"支架" | H23: 配件 | I23: 10 | J23: 8 | K23: =I23*J23 -> 80 | L23: 0.5 | M23: =K23*L23 -> 40 | N23: 10 | O23: =K23-M23+N23 -> 50 | P23: CNY | Q23: TRUE | R23: 已完成 | S23: 王五 | T23: 门店 | U23: 浙江 | V23: Acme, Inc. | W23: 0138000100020 | X23: 第一行 第二行 | Y23: 9.0071993e+15 | Z23: 0 | AA23: Acme, Inc. | AB23: TRUE | AD23: 0.125 | AE23: 45921.5 | AF23: 正常
A24: ORD-202610-100021 | B24: 45920.5 | C24: C003 | D24: ='客户档案'!B5 -> 研发"中心" | E24: 上海 | F24: P001 | G24: ='商品目录'!B3 -> 机械键盘 | H24: 外设 | I24: 2 | J24: 99 | K24: =I24*J24 -> 198 | L24: 0 | M24: =K24*L24 -> 0 | N24: 20 | O24: =K24-M24+N24 -> 218 | P24: CNY | Q24: FALSE | R24: 待付款 | S24: 赵六 | T24: API | U24: 上海 | V24: 研发"中心" | W24: 0138000100021 | Y24: 9.0071993e+15 | Z24: 0 | AA24: 研发"中心" | AB24: FALSE | AD24: 0.125 | AE24: 45922.5 | AF24: 正常
A25: ORD-202610-100022 | B25: 45921.5 | C25: C001 | D25: ='客户档案'!B3 -> 张三 | E25: 北京 | F25: P002 | G25: ='商品目录'!B4 -> 显示器 | H25: 显示设备 | I25: 4 | J25: 129 | K25: =I25*J25 -> 516 | L25: 0.5 | M25: =K25*L25 -> 258 | N25: 0 | O25: =K25-M25+N25 -> 258 | P25: CNY | Q25: TRUE | R25: 已完成 | S25: 李四 | T25: 网页 | U25: 北京 | V25: 张三 | W25: 0138000100022 | X25: 加急,周五前送达 | Y25: 9.0071993e+15 | Z25: 0 | AA25: 张三 | AB25: TRUE | AD25: 0.125 | AE25: 45923.5 | AF25: 正常
A26: ORD-202610-100023 | B26: 45922.5 | C26: C002 | D26: ='客户档案'!B4 -> Acme, Inc. | E26: 深圳 | F26: P003 | G26: ='商品目录'!B5 -> 办公椅 | H26: 家具 | I26: 6 | J26: 45 | K26: =I26*J26 -> 270 | L26: 0 | M26: =K26*L26 -> 0 | N26: 10 | O26: =K26-M26+N26 -> 280 | P26: CNY | Q26: TRUE | R26: 已完成 | S26: 王五 | T26: 门店 | U26: 广东 | V26: Acme, Inc. | W26: 0138000100023 | X26: 收货前联系"前台" | Y26: 9.0071993e+15 | Z26: 0 | AA26: Acme, Inc. | AB26: FALSE | AD26: 0.125 | AE26: 45924.5 | AF26: 正常
A27: ORD-202610-100024 | B27: 45923.5 | C27: C003 | D27: ='客户档案'!B5 -> 研发"中心" | E27: 杭州 | F27: P004 | G27: ='商品目录'!B6 -> 多功能"支架" | H27: 配件 | I27: 8 | J27: 8 | K27: =I27*J27 -> 64 | L27: 0.5 | M27: =K27*L27 -> 32 | N27: 20 | O27: =K27-M27+N27 -> 52 | P27: CNY | Q27: TRUE | R27: 已完成 | S27: 赵六 | T27: API | U27: 浙江 | V27: 研发"中心" | W27: 0138000100024 | X27: 第一行 第二行 | Y27: 9.0071993e+15 | Z27: 0 | AA27: 研发"中心" | AB27: TRUE | AD27: 0.125 | AE27: 45925.5 | AF27: 正常
A28: ORD-202610-100025 | B28: 45924.5 | C28: C001 | D28: ='客户档案'!B3 -> 张三 | E28: 上海 | F28: P001 | G28: ='商品目录'!B3 -> 机械键盘 | H28: 外设 | I28: 10 | J28: 99 | K28: =I28*J28 -> 990 | L28: 0 | M28: =K28*L28 -> 0 | N28: 0 | O28: =K28-M28+N28 -> 990 | P28: CNY | Q28: FALSE | R28: 待付款 | S28: 李四 | T28: 网页 | U28: 上海 | V28: 张三 | W28: 0138000100025 | Y28: 9.0071993e+15 | Z28: 0 | AA28: 张三 | AB28: FALSE | AD28: 0.125 | AE28: 45926.5 | AF28: 正常
A29: ORD-202610-100026 | B29: 45925.5 | C29: C002 | D29: ='客户档案'!B4 -> Acme, Inc. | E29: 北京 | F29: P002 | G29: ='商品目录'!B4 -> 显示器 | H29: 显示设备 | I29: 2 | J29: 129 | K29: =I29*J29 -> 258 | L29: 0.5 | M29: =K29*L29 -> 129 | N29: 10 | O29: =K29-M29+N29 -> 139 | P29: CNY | Q29: TRUE | R29: 已完成 | S29: 王五 | T29: 门店 | U29: 北京 | V29: Acme, Inc. | W29: 0138000100026 | X29: 加急,周五前送达 | Y29: 9.0071993e+15 | Z29: 0 | AA29: Acme, Inc. | AB29: TRUE | AD29: 0.125 | AE29: 45927.5 | AF29: 正常
A30: ORD-202610-100027 | B30: 45926.5 | C30: C003 | D30: ='客户档案'!B5 -> 研发"中心" | E30: 深圳 | F30: P003 | G30: ='商品目录'!B5 -> 办公椅 | H30: 家具 | I30: 4 | J30: 45 | K30: =I30*J30 -> 180 | L30: 0 | M30: =K30*L30 -> 0 | N30: 20 | O30: =K30-M30+N30 -> 200 | P30: CNY | Q30: TRUE | R30: 已完成 | S30: 赵六 | T30: API | U30: 广东 | V30: 研发"中心" | W30: 0138000100027 | X30: 收货前联系"前台" | Y30: 9.0071993e+15 | Z30: 0 | AA30: 研发"中心" | AB30: FALSE | AD30: 0.125 | AE30: 45928.5 | AF30: 正常
A31: ORD-202610-100028 | B31: 45927.5 | C31: C001 | D31: ='客户档案'!B3 -> 张三 | E31: 杭州 | F31: P004 | G31: ='商品目录'!B6 -> 多功能"支架" | H31: 配件 | I31: 6 | J31: 8 | K31: =I31*J31 -> 48 | L31: 0.5 | M31: =K31*L31 -> 24 | N31: 0 | O31: =K31-M31+N31 -> 24 | P31: CNY | Q31: TRUE | R31: 已完成 | S31: 李四 | T31: 网页 | U31: 浙江 | V31: 张三 | W31: 0138000100028 | X31: 第一行 第二行 | Y31: 9.0071993e+15 | Z31: 0 | AA31: 张三 | AB31: TRUE | AD31: 0.125 | AE31: 45929.5 | AF31: 正常
A32: ORD-202610-100029 | B32: 45900.5 | C32: C002 | D32: ='客户档案'!B4 -> Acme, Inc. | E32: 上海 | F32: P001 | G32: ='商品目录'!B3 -> 机械键盘 | H32: 外设 | I32: 8 | J32: 99 | K32: =I32*J32 -> 792 | L32: 0 | M32: =K32*L32 -> 0 | N32: 10 | O32: =K32-M32+N32 -> 802 | P32: CNY | Q32: FALSE | R32: 待付款 | S32: 王五 | T32: 门店 | U32: 上海 | V32: Acme, Inc. | W32: 0138000100029 | Y32: 9.0071993e+15 | Z32: 0 | AA32: Acme, Inc. | AB32: FALSE | AD32: 0.125 | AE32: 45902.5 | AF32: 正常
A33: ORD-202610-100030 | B33: 45901.5 | C33: C003 | D33: ='客户档案'!B5 -> 研发"中心" | E33: 北京 | F33: P002 | G33: ='商品目录'!B4 -> 显示器 | H33: 显示设备 | I33: 10 | J33: 129 | K33: =I33*J33 -> 1290 | L33: 0.5 | M33: =K33*L33 -> 645 | N33: 20 | O33: =K33-M33+N33 -> 665 | P33: CNY | Q33: TRUE | R33: 已完成 | S33: 赵六 | T33: API | U33: 北京 | V33: 研发"中心" | W33: 0138000100030 | X33: 加急,周五前送达 | Y33: 9.0071993e+15 | Z33: 0 | AA33: 研发"中心" | AB33: TRUE | AD33: 0.125 | AE33: 45903.5 | AF33: 正常
A34: ORD-202610-100031 | B34: 45902.5 | C34: C001 | D34: ='客户档案'!B3 -> 张三 | E34: 深圳 | F34: P003 | G34: ='商品目录'!B5 -> 办公椅 | H34: 家具 | I34: 2 | J34: 45 | K34: =I34*J34 -> 90 | L34: 0 | M34: =K34*L34 -> 0 | N34: 0 | O34: =K34-M34+N34 -> 90 | P34: CNY | Q34: TRUE | R34: 已完成 | S34: 李四 | T34: 网页 | U34: 广东 | V34: 张三 | W34: 0138000100031 | X34: 收货前联系"前台" | Y34: 9.0071993e+15 | Z34: 0 | AA34: 张三 | AB34: FALSE | AD34: 0.125 | AE34: 45904.5 | AF34: 正常
A35: ORD-202610-100032 | B35: 45903.5 | C35: C002 | D35: ='客户档案'!B4 -> Acme, Inc. | E35: 杭州 | F35: P004 | G35: ='商品目录'!B6 -> 多功能"支架" | H35: 配件 | I35: 4 | J35: 8 | K35: =I35*J35 -> 32 | L35: 0.5 | M35: =K35*L35 -> 16 | N35: 10 | O35: =K35-M35+N35 -> 26 | P35: CNY | Q35: TRUE | R35: 已完成 | S35: 王五 | T35: 门店 | U35: 浙江 | V35: Acme, Inc. | W35: 0138000100032 | X35: 第一行 第二行 | Y35: 9.0071993e+15 | Z35: 0 | AA35: Acme, Inc. | AB35: TRUE | AD35: 0.125 | AE35: 45905.5 | AF35: 正常
A36: ORD-202610-100033 | B36: 45904.5 | C36: C003 | D36: ='客户档案'!B5 -> 研发"中心" | E36: 上海 | F36: P001 | G36: ='商品目录'!B3 -> 机械键盘 | H36: 外设 | I36: 6 | J36: 99 | K36: =I36*J36 -> 594 | L36: 0 | M36: =K36*L36 -> 0 | N36: 20 | O36: =K36-M36+N36 -> 614 | P36: CNY | Q36: FALSE | R36: 待付款 | S36: 赵六 | T36: API | U36: 上海 | V36: 研发"中心" | W36: 0138000100033 | Y36: 9.0071993e+15 | Z36: 0 | AA36: 研发"中心" | AB36: FALSE | AD36: 0.125 | AE36: 45906.5 | AF36: 正常
A37: ORD-202610-100034 | B37: 45905.5 | C37: C001 | D37: ='客户档案'!B3 -> 张三 | E37: 北京 | F37: P002 | G37: ='商品目录'!B4 -> 显示器 | H37: 显示设备 | I37: 8 | J37: 129 | K37: =I37*J37 -> 1032 | L37: 0.5 | M37: =K37*L37 -> 516 | N37: 0 | O37: =K37-M37+N37 -> 516 | P37: CNY | Q37: TRUE | R37: 已完成 | S37: 李四 | T37: 网页 | U37: 北京 | V37: 张三 | W37: 0138000100034 | X37: 加急,周五前送达 | Y37: 9.0071993e+15 | Z37: 0 | AA37: 张三 | AB37: TRUE | AD37: 0.125 | AE37: 45907.5 | AF37: 正常
A38: ORD-202610-100035 | B38: 45906.5 | C38: C002 | D38: ='客户档案'!B4 -> Acme, Inc. | E38: 深圳 | F38: P003 | G38: ='商品目录'!B5 -> 办公椅 | H38: 家具 | I38: 10 | J38: 45 | K38: =I38*J38 -> 450 | L38: 0 | M38: =K38*L38 -> 0 | N38: 10 | O38: =K38-M38+N38 -> 460 | P38: CNY | Q38: TRUE | R38: 已完成 | S38: 王五 | T38: 门店 | U38: 广东 | V38: Acme, Inc. | W38: 0138000100035 | X38: 收货前联系"前台" | Y38: 9.0071993e+15 | Z38: 2 | AA38: Acme, Inc. | AB38: FALSE | AD38: 0.125 | AE38: 45908.5 | AF38: 正常
A39: ORD-202610-100036 | B39: 45907.5 | C39: C003 | D39: ='客户档案'!B5 -> 研发"中心" | E39: 杭州 | F39: P004 | G39: ='商品目录'!B6 -> 多功能"支架" | H39: 配件 | I39: 2 | J39: 8 | K39: =I39*J39 -> 16 | L39: 0.5 | M39: =K39*L39 -> 8 | N39: 20 | O39: =K39-M39+N39 -> 28 | P39: CNY | Q39: TRUE | R39: 已完成 | S39: 赵六 | T39: API | U39: 浙江 | V39: 研发"中心" | W39: 0138000100036 | X39: 第一行 第二行 | Y39: 9.0071993e+15 | Z39: 0 | AA39: 研发"中心" | AB39: TRUE | AD39: 0.125 | AE39: 45909.5 | AF39: 正常
A40: ORD-202610-100037 | B40: 45908.5 | C40: C001 | D40: ='客户档案'!B3 -> 张三 | E40: 上海 | F40: P001 | G40: ='商品目录'!B3 -> 机械键盘 | H40: 外设 | I40: 4 | J40: 99 | K40: =I40*J40 -> 396 | L40: 0 | M40: =K40*L40 -> 0 | N40: 0 | O40: =K40-M40+N40 -> 396 | P40: CNY | Q40: FALSE | R40: 待付款 | S40: 李四 | T40: 网页 | U40: 上海 | V40: 张三 | W40: 0138000100037 | Y40: 9.0071993e+15 | Z40: 0 | AA40: 张三 | AB40: FALSE | AD40: 0.125 | AE40: 45910.5 | AF40: 正常
...

Sheet 商品目录
A1: 商品目录与库存
A2: 商品编号 | B2: 名称 | C2: 分类 | D2: 单价 | E2: 库存 | F2: 在售 | G2: 说明
A3: P001 | B3: 机械键盘 | C3: 外设 | D3: 99 | E3: 1000 | F3: TRUE | G3: 仓库,需复核
A4: P002 | B4: 显示器 | C4: 显示设备 | D4: 129 | E4: 800 | F4: TRUE | G4: 仓库,需复核
A5: P003 | B5: 办公椅 | C5: 家具 | D5: 45 | E5: 600 | F5: TRUE | G5: 仓库,需复核
A6: P004 | B6: 多功能"支架" | C6: 配件 | D6: 8 | E6: 400 | F6: FALSE | G6: 仓库,需复核

Sheet 客户档案
A1: 客户主数据
A2: 客户编号 | B2: 名称 | C2: 电话 | D2: 地区 | E2: 等级 | F2: 注册日期 | G2: 启用 | H2: 备注
A3: C001 | B3: 张三 | C3: 0013800012345 | D3: 上海 | E3: 普通 | F3: 45000.5 | G3: TRUE | H3: 首选联系人 备用联系人
A4: C002 | B4: Acme, Inc. | C4: 0013800012345 | D4: 北京 | E4: VIP | F4: 45001.5 | G4: TRUE | H4: 首选联系人 备用联系人
A5: C003 | B5: 研发"中心" | C5: 0013800012345 | D5: 深圳 | E5: VIP | F5: 45002.5 | G5: TRUE | H5: 首选联系人 备用联系人

Sheet 月度汇总
A1: 月度经营汇总
A2: 指标 | B2: 数值 | C2: 口径 | F2: 备注
A3: 订单数 | B3: =COUNTA('订单明细'!A4:A1007) -> 1000 | C3: 不含分隔空行
A4: 原价金额 | B4: =SUM('订单明细'!K4:K1007) -> 421500 | C4: 含隐藏行
A5: 优惠金额 | B5: =SUM('订单明细'!M4:M1007) -> 102750
A6: 运费 | B6: =SUM('订单明细'!N4:N1007) -> 9990
A7: 应付金额 | B7: =SUM('订单明细'!O4:O1007) -> 328740
A8: 已付款订单 | B8: =COUNTIF('订单明细'!Q4:Q1007,TRUE) -> 750
A9: 欠款金额 | B9: =SUMIF('订单明细'!Q4:Q1007,FALSE,'订单明细'!O4:O1007) -> 150990

Sheet 说明与异常
A1: 数据字典与异常样例
A2: 场景 | B2: 整数 | C2: 小数 | D2: 布尔 | E2: 文本 | F2: 错误 | G2: 日期 | H2: 备注
A3: 负数与零 | B3: -100 | C3: -0.125 | D3: FALSE | E3: 00000
A4: 异常计算 | B4: 0 | D4: TRUE | E4: 待修复 | F4: #DIV/0!
A5: 缺失关联 | F5: #N/A | H5: 客户,商品缺失
A6: 非法值 | F6: #VALUE! | H6: 检查"类型"
A7: 时间字段 | G7: 45900.5 | H7: 底层日期序列数
